Workbook

Sheet Processo
C9: 1 | J9: 2 | Q9: 3
W17: PROBLEMA
C28: 4 | J28: 5 | Q28: 6
C39: 1 | D39: =D9 -> 0 | AF39: Não domina o processo comercial
C47: 2 | D47: =K9 -> 0 | AF47: ='2. Planos de Ação'!B12 -> 0
C55: 3 | D55: =R9 -> 0 | AF55: ='2. Planos de Ação'!B13 -> 0
C63: 4 | D63: =D23 -> 0 | AF63: ='2. Planos de Ação'!B14 -> 0
C71: 5 | D71: =K23 -> 0 | AF71: ='2. Planos de Ação'!B15 -> 0
C79: 6 | D79: =R23 -> 0 | AF79: ='2. Planos de Ação'!B16 -> 0

Sheet 0. Árvore de Alavancas
A5: ANÁLISE DO FENÔMENO

Sheet 1. Plano Comercial
C2: Dicas de Uso: | I2: Glossário para encontrar os dados a serem preenchidos
C3: Células em amarelo são editáveis e onde você insere os seus dados (Input). | I3: *1 > Dado encontrado no HUB->Dashboard->Performance
C4: Células em branco são cálculos automáticos a partir do preenchimento das células em amarelo (Output). | I4: *2 > Dado deve ser inputado por conta própria e validado pela liderança
C5: Células em verde são os esforços mensais necessários para o atingimento das premissas (Output).
C7: Passo 1 - Preencha
C8: Premissas Iniciais - Hunter | E8: Glossário
C9: 1. NET Atual | D9: 18000000 | E9: *1
C10: 2. Qtde Total Clientes Ativos Atuais | D10: 116 | E10: *1
C11: 1. SoW atual | D11: 0.4 | E11: *1
C12: 2. Potencial dentro da base | D12: =D9/(D11)-D9 -> 27000000
C13: 3. Ticket Médio Potencial Dentro da Base | D13: =D12/D10 -> 232758.62
C14: 4. Churn esperado (%) / mês | D14: 0.03
C15: 4.1. Churn Esperado (R$) / mês | D15: =(D14*D9) -> 540000
C16: 4.2. Churn Esperado (R$) / período | D16: =D15*D24 -> 6480000
C17: 1. ROA Atual (comissionamento líquido - depois de imposto e rebate) | D17: 0.004 | E17: *2
C18: 2. Comissionamento Mensal Bruto | D18: =(D9*D17/12) -> 6000
C22: Passo 2 - Preencha | G22: Passo 3 - Preencha | M22: RESUMO O PLANO COMERCIAL - HUNTER E FARMER - Apenas para Leitura - NÃO Preencha! | R22: Memória de Cálculo dos Passos 3 e 4 - Apenas para Leitura - NÃO Preencha!
C23: Objetivos e Desafios | E23: Glossário
C24: 1. Horizonte de Análise (meses) | D24: 12 | E24: *2 | G24: Pensando no SEU Processo/Funil Comercial durante atividade HUNTING (Prospecção de Novos Clientes), RESPONDA: | M24: Plano Comercial Hunter | R24: Prospecção Novos Clientes (Hunter) | S24: Hunting | T24: Glossário
C25: 2. Objetivo de Comissionamento Mensal | D25: 15000 | G25: Qual % de Conexões que viram Agendamento de Reunião de Mapeamento (1a Reunião)? (# Diagnósticos / # Conexões) | K25: 0.5 | R25: 1. Captação Novos Clientes | S25: =D34 -> 26784000
C26: 3. Objetivo de ROA (líquido - depois de impostos e rebate) | D26: 0.004 | E26: *2 | G26: Qual % de Diagnósticos (1a Reunião) que viram Reuniões de Apresentação de Proposta (2a Reunião)? ( # Propostas Comerciais / # Diagnósticos ) | K26: 0.7 | M26: Planejado | N26: Mensal | O26: Semanal | P26: Diário | R26: 1. Captação Novos Clientes/Mês | S26: =S25/D24 -> 2232000
C27: 4. NET Projetado | D27: =D25*12/D26 -> 45000000 | G27: Qual % de Propostas (2a reunião) que viram Abertura de Conta (Habilitação)? (# Habilitações / # Propostas) | K27: 0.6 | M27: # Conexões Necessárias | N27: =S29 -> 58 | O27: =ROUNDUP(N27/4,0) -> 15 | P27: =ROUNDUP(O27/5,0) -> 3 | R27: 2. Ticket Médio de 1º aporte Objetivo | S27: =K29 -> 300000 | T27: *2
C28: 5. Objetivo de CAPTAÇÃO / Mês | D28: =(D27-D9)/D24 -> 2250000 | G28: Qual % de Contas Abertas (Habilitação) que viram TED (Contas Ativadas)?(# Contas Ativadas / # Habilitações) | K28: 0.7 | M28: # Diagnósticos Necessários | N28: =S32 -> 29 | O28: =ROUNDUP(N28/4,0) -> 8 | P28: =ROUNDUP(O28/5,0) -> 2 | R28: 3. # Conexão Total | S28: =S29*D24 -> 696
C29: 6. Captação Alvo no Período + Churn Período | D29: =(D28*D24)+D16 -> 33480000 | G29: Qual Ticket Médio de 1º Aporte Objetivo? | K29: 300000 | M29: # Propostas Comerciais Hunter Necessárias | N29: =S34 -> 20 | O29: =ROUNDUP(N29/4,0) -> 5 | P29: =ROUNDUP(O29/5,0) -> 1 | R29: 3.2 # Conexão / Mês | S29: =ROUNDUP((S32/S31),) -> 58
C30: 7. Atingimento da Meta no Período | D30: =IFERROR(((D28*D24)+D16),"") -> 33480000 | M30: Ticket Médio 1º Aporte Alvo | N30: =S27 -> 300000 | R30: 3.3 # Conexão / Dia | S30: =ROUNDUP((S29/22),) -> 3
C31: 8. % Captação dentro da Base | D31: 0.2 | E31: *2 | R31: 4.Qual % de Conexões que viram Agendamento de Reunião de Mapeamento (1a Reunião)? (# Diagnósticos / # Conexões) | S31: =K25 -> 0.5 | T31: *2
C32: 8.1 % Captação fora da Base | D32: =1-D31 -> 0.8 | M32: Captação Mensal Alvo | N32: =(D30*D32)/D24 -> 2232000 | R32: 4.1. # Diagnósticos / Mês | S32: =ROUNDUP((S34/S33),) -> 29
C33: 9. R$ Captação dentro da Base | D33: =D30*D31 -> 6696000 | R33: 5. Qual % de Diagnósticos (1a Reunião) que viram Reuniões de Apresentação de Proposta (2a Reunião)? ( # Propostas Comerciais / # Diagnósticos ) | S33: =K26 -> 0.7 | T33: *2
C34: 10.1 % Captação fora da Base | D34: =D30*D32 -> 26784000 | R34: 5.1. # Proposta Comercial / Mês | S34: =S36/S35 -> 20
G35: Passo 4 - Preencha | M35: Plano Comercial Farmer | R35: 6.Qual % de Propostas (2a reunião) que viram Abertura de Conta (Habilitação)? (# Habilitações / # Propostas) | S35: =K27 -> 0.6 | T35: *2
R36: 6.1. # Contas Abertas / mês | S36: =IFERROR(ROUNDUP(S38*S40,0),"") -> 12
G37: Pensando no atendimento a sua BASE de JÁ CLIENTES (Carteira), durante atividade FARMER: RESPONDA: | M37: Orçado | N37: Mensal | O37: Semanal | P37: Diário | R37: 7. Qual % de Contas Abertas (Habilitação) que viram TED (Contas Ativadas)?(# Contas Ativadas / # Habilitações) | S37: =K28 -> 0.7 | T37: *2
G38: Qual % de Mapeamentos feitos com os clientes da Base que viram Envio de Proposta para o cliente? (# Propostas Enviadas / # Mapeamentos) | K38: 0.7 | M38: # Mapeamentos de Clientes Base Necessários | N38: =S51 -> 7.1428571 | O38: =ROUNDUP(N38/4,0) -> 2 | P38: =ROUNDUP(O38/5,0) -> 1 | R38: 7.2. # Ativação / Contas Abertas | S38: =1/S37 -> 1.4285714
G39: Qual % Propostas Enviadas que viram TED enviadas (Propostas Ativadas)? ( # TEDs ou Propostas Ativadas / # Propostas Enviadas ) | K39: 0.7 | M39: # Propostas Farmer Necessárias | N39: =S55 -> 5 | O39: =ROUNDUP(N39/4,0) -> 2 | P39: =ROUNDUP(O39/5,0) -> 1 | R39: 8. # Ativações no Período | S39: =IFERROR(S25/S27,"") -> 89.28
G40: Plano FARMER é suficiente? | K40: =IF(S50>D10,"Não, número de clientes insuficiêntes","Sim") -> Sim | M40: Ticket Médio Alvo | N40: =S48 -> 232758.62 | R40: 8.1. # Ativações / mês | S40: =ROUNDUP(S39/D24,0) -> 8
J41: *Não avançar caso o plano não seja suficiente | R41: 9. % Tx. Conversão Total (# Ativações / # Conexões) | S41: =IFERROR(S40/S29,"") -> 0.13793103
M43: Captação Mensal Alvo | N43: =(D30*D31)/D24 -> 558000
M45: Captação Mensal Alvo TOTAL: Hunter + Farmer | N45: =N32+N43 -> 2790000 | R45: Prospecção Base (Farmer) | S45: Farming | T45: Glossário
G46: Passo 5 (Análise - ROA) - Preencha | R46: 1. Captação Clientes Ativos | S46: =D33 -> 6696000
G47: Objetivo | R47: 1.1. Captação Clientes Ativos/Mês | S47: =IFERROR(S46/D24,"") -> 558000
...

Sheet Resumo
G18: ='1. Plano Comercial'!S32/'1. Plano Comercial'!S29 -> 0.5
M21: ='1. Plano Comercial'!S34/'1. Plano Comercial'!S32 -> 0.68965517
H25: ='1. Plano Comercial'!S36/'1. Plano Comercial'!S34 -> 0.6
M28: ='1. Plano Comercial'!S40/'1. Plano Comercial'!S36 -> 0.66666667

Sheet 2. Planos de Ação
B2: Dicas de Uso: | H2: Glossário para encontrar os dados a serem preenchidos
B3: Células em amarelo são editáveis e onde você insere os seus dados (Input). | H3: *1 >Dado encontrado no HUB->Dashboard->Performance
B4: Células em branco são cálculos automáticos a partir do preenchimento das células em amarelo (Output). | H4: *2> Dado deve ser inputado por conta própria e validado pela liderança
B5: Células em verde são os esforços mensais necessários para o atingimento das premissas (Output). | H5: *3> Dado encontrado no Salesforce
B8: Plano de Ação Mensal: Assessor
B9: Problema | C9: Causa | D9: Nome Ação | E9: Indicador Fim | F9: Prazo | G9: Responsável | H9: Como? | I9: # oportunidades esperadas | J9: $/oportunidade | K9: Potencial Identificado | L9: Taxa de Sucesso esperada | M9: Resultado Esperado | N9: % atingimento da meta | O9: Indicador Meio - Hunter | S9: Indicador Meio - Farmer
K10: =J10*I10 -> 0 | M10: =L10*K10 -> 0 | N10: =M10/($C$31+$C$42) -> 0 | O10: # Conexões | P10: # Diagnósticos | Q10: # Propostas Comerciais Hunter | S10: # Mapeamentos Clientes Base | T10: # Propostas Comerciais Farmer
O11: =I10*L10 -> 0 | P11: =O11*'1. Plano Comercial'!S31 -> 0 | Q11: =P11*'1. Plano Comercial'!S33 -> 0 | S11: 0 | T11: 0
K12: =J12*I12 -> 0 | M12: =L12*K12 -> 0 | N12: =M12/($C$31+$C$42) -> 0 | O12: =I12*L12 -> 0 | P12: =O12*L12 -> 0 | Q12: =P12*50% -> 0 | S12: 0 | T12: 0
K13: =J13*I13 -> 0 | M13: =L13*K13 -> 0 | N13: =M13/($C$31+$C$42) -> 0 | O13: 0 | P13: 0 | Q13: 0 | S13: =I13*L13 -> 0 | T13: =S13*'1. Plano Comercial'!S49 -> 0
K14: =J14*I14 -> 0 | M14: =L14*K14 -> 0 | N14: =M14/($C$31+$C$42) -> 0 | O14: 0 | P14: 0 | Q14: 0 | S14: 0 | T14: 0
K15: =J15*I15 -> 0 | M15: =L15*K15 -> 0 | N15: =M15/($C$31+$C$42) -> 0 | O15: 0 | P15: 0 | Q15: 0 | S15: 0 | T15: 0
K16: =J16*I16 -> 0 | M16: =L16*K16 -> 0 | N16: =M16/($C$31+$C$42) -> 0 | O16: 0 | P16: 0 | Q16: 0 | S16: 0 | T16: 0
K17: =J17*I17 -> 0 | M17: =L17*K17 -> 0 | N17: =M17/($C$31+$C$42) -> 0 | O17: 0 | P17: 0 | Q17: 0 | S17: 0 | T17: 0
K18: =J18*I18 -> 0 | M18: =L18*K18 -> 0 | N18: =M18/($C$31+$C$42) -> 0 | O18: 0 | P18: 0 | Q18: 0 | S18: 0 | T18: 0
H19: TOTAL | I19: =SUM(I10:I15) -> 0 | J19: - | K19: =SUM(K10:K15) -> 0 | L19: - | M19: =SUM(M10:M15) -> 0 | N19: =SUM(N10:N15) -> 0 | O19: =SUM(O11:O18) -> 0 | P19: =SUM(P11:P18) -> 0 | Q19: =SUM(Q11:Q18) -> 0 | S19: =SUM(S11:S18) -> 0 | T19: =SUM(T11:T18) -> 0
B20: LEMBRE-SE SEMPRE DO OBJETIVO - PONTO DE PARTIDA! | N20: Esforços Totais são suficientes? | O20: =IF(O19>=C26,"Sim","Não") -> Não | P20: =IF(P19>=C27,"Sim","Não") -> Não | Q20: =IF(Q19>=C28,"Sim","Não") -> Não | S20: =IF(S19>=C38,"Sim","Não") -> Não | T20: =IF(T19>=C39,"Sim","Não") -> Não
B22: Plano Comercial Hunter
B25: Orçado | C25: Mensal | D25: Semanal | E25: Diário
B26: Conexão Efetuadas | C26: ='1. Plano Comercial'!S29 -> 58 | D26: =ROUNDUP(C26/4,0) -> 15 | E26: =ROUNDUP(D26/5,0) -> 3
B27: Diagnósticos Efetuados | C27: ='1. Plano Comercial'!S32 -> 29 | D27: =ROUNDUP(C27/4,0) -> 8 | E27: =ROUNDUP(D27/5,0) -> 2
B28: Propostas Comerciais Hunter | C28: ='1. Plano Comercial'!S34 -> 20 | D28: =ROUNDUP(C28/4,0) -> 5 | E28: =ROUNDUP(D28/5,0) -> 1
B29: Ticket Médio | C29: ='1. Plano Comercial'!S27 -> 300000
B31: Captação Mensal para Meta | C31: =('1. Plano Comercial'!D30*'1. Plano Comercial'!D32)/'1. Plano Comercial'!D24 -> 2232000
B34: Plano Comercial Farmer
B37: Orçado | C37: Mensal | D37: Semanal | E37: Diário
B38: # Mapemaneto Clientes Base | C38: ='1. Plano Comercial'!S51 -> 7.1428571 | D38: =ROUNDUP(C38/4,0) -> 2 | E38: =ROUNDUP(D38/5,0) -> 1
B39: # Propostas Farmer Enviadas | C39: ='1. Plano Comercial'!S55 -> 5 | D39: =ROUNDUP(C39/4,0) -> 2 | E39: =ROUNDUP(D39/5,0) -> 1
B40: Ticket Médio | C40: ='1. Plano Comercial'!S48 -> 232758.62
B42: Captação Mensal para a meta | C42: =('1. Plano Comercial'!D30*'1. Plano Comercial'!D31)/'1. Plano Comercial'!D24 -> 558000
B44: Captação Mensal Alvo TOTAL: Hunter + Farmer | C44: =C31+C42 -> 2790000

Sheet 3. Reunião 1-1 Acompanhamento
B2: Dicas de Uso: | I2: Glossário para encontrar os dados a serem preenchidos
B3: Células em amarelo são editáveis e onde você insere os seus dados (Input). | I3: *1 >Dado encontrado no HUB->Dashboard->Performance
B4: Células em branco são cálculos automáticos a partir do preenchimento das células em amarelo (Output). | I4: *2> Dado deve ser inputado por conta própria e validado pela liderança
B5: Células em verde são os esforços mensais necessários para o atingimento das premissas (Output).
B7: 1:1 Semanal
B9: Assessor: | C9: Thiago Fischer | H9: Mês | I9: Junho
B10: Meta Cap | C10: ='1. Plano Comercial'!D30/'1. Plano Comercial'!D24 -> 2790000 | E10: *Considera obj. de captação + resgates esperado (Churn) | H10: Semanas Atual | I10: =COUNTA(K17,K29,K41,K53) -> 1
B11: Cap Acum. | C11: =SUM(K17,K29,K41,K53) -> 0 | H11: Semanas Mês | I11: 4
B12: Pipeline Acum. | C12: =SUM(K19,K31,K43,K55) -> 0 | K12: PREENCHA OS REALIZADOS NESTA COLUNA
B13: Tx. Conversão Pipeline | C13: 0.3 | F13: PREENCHA O % DE CONVERSÃO DE PIPELINE ESTIMADO, ATÉ QUE VOCÊ TENHA O REALIZADO DE FATO
B15: Semana 1 | H15: Planejado | K15: Realizado/Gerado | M15: Esforços suficientes?
K16: (Preencher valores abaixo)
B17: Resultado | E17: Captação da semana | H17: =C10/I11 -> 697500 | M17: =IF(K17>=H17,"Sim","Não") -> Não
B19: Pipeline (Oportunidade) | E19: Pipeline gerado na semana | H19: =C10/I11/C13 -> 2325000 | M19: =IF(K19>=H19,"Sim","Não") -> Não
B21: Atividades Feitas (Esforços) | E21: #Conexão / Agendamento de Reuniões | H21: ='2. Planos de Ação'!C26/I11 -> 14.5 | M21: =IF(K21>=H21,"Sim","Não") -> Não
E22: #Diagnóstico / Reuniões de Mapeamento (1ª Reunião) | H22: ='2. Planos de Ação'!C27/I11 -> 7.25 | M22: =IF(K22>=H22,"Sim","Não") -> Não
E23: #Reunião de Apresentações de Propostas (2º Reunião) | H23: ='2. Planos de Ação'!C28/I11 -> 5 | M23: =IF(K23>=H23,"Sim","Não") -> Não
E24: #Mapeamentos Clientes Base | H24: ='2. Planos de Ação'!C38/I11 -> 1.7857143 | M24: =IF(K24>=H24,"Sim","Não") -> Não
E25: #Propostas Enviadas - Farmer | H25: ='2. Planos de Ação'!C39/I11 -> 1.25 | M25: =IF(K25>=H25,"Sim","Não") -> Não
B27: Semana 2 | H27: Planejado | K27: Realizado | M27: Esforços suficientes?
K28: (Preencher valores abaixo)
B29: Resultado | E29: Captação da semana | H29: =IF((C10/I11)+(H17-K17)<0,0,(C10/I11)+(H17-K17)) -> 1395000 | K29: 0 | M29: =IF(K29>=H29,"Sim","Não") -> Não
B31: Pipeline (Oportunidade) | E31: Pipeline gerado na semana | H31: =C10/I11/C13 -> 2325000 | M31: =IF(K31>=H31,"Sim","Não") -> Não
B33: Atividades Feitas | E33: #Conexão / Agendamento de Reuniões | H33: =IF('2. Planos de Ação'!$C$26/I11+(H21-K21)<H21,H$21,'2. Planos de Ação'!$C$26/I11+(H21-K21)) -> 29 | M33: =IF(K33>=H33,"Sim","Não") -> Não
E34: #Diagnóstico / Reuniões de Mapeamento (1ª Reunião) | H34: =IF('2. Planos de Ação'!$C$27/I11+(H22-K22)<H22,$H$22,'2. Planos de Ação'!$C$27/I11+(H22-K22)) -> 14.5 | M34: =IF(K34>=H34,"Sim","Não") -> Não
E35: #Reunião de Apresentações de Propostas (2º Reunião) | H35: =IF('2. Planos de Ação'!$C$28/I11+(H23-K23)<H23,$H$23,'2. Planos de Ação'!$C$28/I11+(H23-K23)) -> 10 | M35: =IF(K35>=H35,"Sim","Não") -> Não
E36: #Mapeamentos Clientes Base | H36: =IF('2. Planos de Ação'!$C$38/I11+(H24-K24)<H24,$H$24,'2. Planos de Ação'!$C$38/I11+(H24-K24)) -> 3.5714286 | M36: =IF(K36>=H36,"Sim","Não") -> Não
E37: #Propostas Enviadas - Farmer | H37: =IF('2. Planos de Ação'!$C$39/I11+(H25-K25)<H25,$H$25,'2. Planos de Ação'!$C$39/I11+(H25-K25)) -> 2.5 | M37: =IF(K37>=H37,"Sim","Não") -> Não
B39: Semana 3 | H39: Planejado | K39: Realizado | M39: Esforços suficientes?
K40: (Preencher valores abaixo)
B41: Resultado | E41: Captação da semana | H41: =IF((C10/I11)+(H29-K29)<0,0,(C10/I11)+(H29-K29)) -> 2092500 | M41: =IF(K41>=H41,"Sim","Não") -> Não
B43: Pipeline (Oportunidade) | E43: Pipeline gerado na semana | H43: =C10/I11/C13 -> 2325000 | M43: =IF(K43>=H43,"Sim","Não") -> Não
B45: Atividades Feitas | E45: #Conexão / Agendamento de Reuniões | H45: =IF('2. Planos de Ação'!$C$26/I11+(H33-K33)<H33,H$21,'2. Planos de Ação'!$C$26/I11+(H33-K33)) -> 43.5 | M45: =IF(K45>=H45,"Sim","Não") -> Não
E46: #Diagnóstico / Reuniões de Mapeamento (1ª Reunião) | H46: =IF('2. Planos de Ação'!$C$27/I11+(H34-K34)<H34,$H$22,'2. Planos de Ação'!$C$27/I11+(H34-K34)) -> 21.75 | M46: =IF(K46>=H46,"Sim","Não") -> Não
E47: #Reunião de Apresentações de Propostas (2º Reunião) | H47: =IF('2. Planos de Ação'!$C$28/I11+(H35-K35)<H35,$H$23,'2. Planos de Ação'!$C$28/I11+(H35-K35)) -> 15 | M47: =IF(K47>=H47,"Sim","Não") -> Não
E48: #Mapeamentos Clientes Base | H48: =IF('2. Planos de Ação'!$C$38/I11+(H36-K36)<H36,$H$24,'2. Planos de Ação'!$C$38/I11+(H36-K36)) -> 5.3571429 | M48: =IF(K48>=H48,"Sim","Não") -> Não
E49: #Propostas Enviadas - Farmer | H49: =IF('2. Planos de Ação'!$C$39/I11+(H37-K37)<H37,$H$25,'2. Planos de Ação'!$C$39/I11+(H37-K37)) -> 3.75 | M49: =IF(K49>=H49,"Sim","Não") -> Não
B51: Semana 4 | H51: Planejado | K51: Realizado | M51: Esforços suficientes?
K52: (Preencher valores abaixo)
B53: Resultado | E53: Captação da semana | H53: =IF((C10/I11)+(H41-K41)<0,0,(C10/I11)+(H41-K41)) -> 2790000 | M53: =IF(K53>=H53,"Sim","Não") -> Não
...
